<?xml version="1.0" encoding="UTF-8"?>
<!-- Generated by org.testng.reporters.JUnitXMLReporter -->
<testsuite ignored="2" hostname="MacBook-Pro-Astaroth.local" failures="1" tests="1" name="Default test" time="74.275" errors="0" timestamp="12 Sep 2021 16:24:54 GMT">
  <testcase classname="qaautomation.august2021.FailedAppTest" name="usernameCorrectAndpasswordCorrect" time="48.298">
    <failure type="java.lang.AssertionError" message="expected:&amp;lt;fullstackdemo&amp;gt; but was:&amp;lt;fullstack&amp;gt;">
      <![CDATA[java.lang.AssertionError: expected:<fullstackdemo> but was:<fullstack>
at org.testng.AssertJUnit.assertEquals(AssertJUnit.java:101)
at org.testng.AssertJUnit.assertEquals(AssertJUnit.java:108)
at qaautomation.august2021.FailedAppTest.usernameCorrectAndpasswordCorrect(FailedAppTest.java:53)
at java.base/jdk.internal.reflect.NativeMethodAccessorImpl.invoke0(Native Method)
at java.base/jdk.internal.reflect.NativeMethodAccessorImpl.invoke(NativeMethodAccessorImpl.java:78)
at java.base/jdk.internal.reflect.DelegatingMethodAccessorImpl.invoke(DelegatingMethodAccessorImpl.java:43)
at java.base/java.lang.reflect.Method.invoke(Method.java:567)
at org.testng.internal.MethodInvocationHelper.invokeMethod(MethodInvocationHelper.java:124)
at org.testng.internal.Invoker.invokeMethod(Invoker.java:583)
at org.testng.internal.Invoker.invokeTestMethod(Invoker.java:719)
at org.testng.internal.Invoker.invokeTestMethods(Invoker.java:989)
at org.testng.internal.TestMethodWorker.invokeTestMethods(TestMethodWorker.java:125)
at org.testng.internal.TestMethodWorker.run(TestMethodWorker.java:109)
at org.testng.TestRunner.privateRun(TestRunner.java:648)
at org.testng.TestRunner.run(TestRunner.java:505)
at org.testng.SuiteRunner.runTest(SuiteRunner.java:455)
at org.testng.SuiteRunner.runSequentially(SuiteRunner.java:450)
at org.testng.SuiteRunner.privateRun(SuiteRunner.java:415)
at org.testng.SuiteRunner.run(SuiteRunner.java:364)
at org.testng.SuiteRunnerWorker.runSuite(SuiteRunnerWorker.java:52)
at org.testng.SuiteRunnerWorker.run(SuiteRunnerWorker.java:84)
at org.testng.TestNG.runSuitesSequentially(TestNG.java:1208)
at org.testng.TestNG.runSuitesLocally(TestNG.java:1137)
at org.testng.TestNG.runSuites(TestNG.java:1049)
at org.testng.TestNG.run(TestNG.java:1017)
at org.testng.remote.AbstractRemoteTestNG.run(AbstractRemoteTestNG.java:115)
at org.testng.remote.RemoteTestNG.initAndRun(RemoteTestNG.java:251)
at org.testng.remote.RemoteTestNG.main(RemoteTestNG.java:77)
]]>
    </failure>
  </testcase> <!-- usernameCorrectAndpasswordCorrect -->
  <testcase classname="qaautomation.august2021.FailedAppTest" name="usernameCorrectAndpasswordIncorrect" time="0.0">
    <ignored/>
  </testcase> <!-- usernameCorrectAndpasswordIncorrect -->
  <testcase classname="qaautomation.august2021.FailedAppTest" name="usernameIncorrectAndpasswordCorrect" time="0.0">
    <ignored/>
  </testcase> <!-- usernameIncorrectAndpasswordCorrect -->
</testsuite> <!-- Default test -->
